Time: 11:27:59
Temperature: 27.767894322052598 C
Pressure: 1005.3772271680564 hPa
Humidity: 57.259942141796984 % rH
--------------------
Time: 11:28:01
Temperature: 27.74756325641647 C
Pressure: 1005.4535558464485 hPa
Humidity: 57.259003717519725 % rH
--------------------
Time: 11:28:03
Temperature: 27.513756336295046 C
Pressure: 1005.0117424775086 hPa
Humidity: 57.243076290392686 % rH
--------------------
Time: 11:28:05
Temperature: 27.752646022388944 C
Pressure: 1005.4069822711526 hPa
Humidity: 57.29000416304771 % rH
--------------------
Time: 11:28:07
Temperature: 27.757728788652457 C
Pressure: 1005.3879000982653 hPa
Humidity: 57.259472948076684 % rH
--------------------
Time: 11:28:09
Temperature: 27.74756325641647 C
Pressure: 1005.3435887645073 hPa
Humidity: 57.22823795752691 % rH
--------------------
Time: 11:28:11
Temperature: 27.732314960245276 C
Pressure: 1005.2908692188535 hPa
Humidity: 57.25829980261555 % rH
--------------------
Time: 11:28:13
Temperature: 27.49342532886658 C
Pressure: 1005.0330689944717 hPa
Humidity: 57.25751041231364 % rH
--------------------
Time: 11:28:15
Temperature: 27.630659719376126 C
Pressure: 1005.2601230884552 hPa
Humidity: 57.25360491847876 % rH
--------------------
Time: 11:28:17
Temperature: 27.732314960245276 C
Pressure: 1005.4283246369337 hPa
Humidity: 57.2685546481 % rH
--------------------
Predicted Temperature for the next 10 minutes: 27.67638221343222
Predicted Humidity for the next 10 minutes: 57.25677148734316
Predicted Pressure for the next 10 minutes: 1005.28848008766
27.732314960245276
57.2685546481
1005.4283246369337
现在的天气是：Cloudy
预测的天气是：Cloudy
Traceback (most recent call last):
  File "/home/pi/SWS3025/env/lib/python3.11/site-packages/urllib3/connection.py", line 196, in _new_conn
    sock = connection.create_connection(
           ^^^^^^^^^^^^^^^^^^^^^^^^^^^^^
  File "/home/pi/SWS3025/env/lib/python3.11/site-packages/urllib3/util/connection.py", line 85, in create_connection
    raise err
  File "/home/pi/SWS3025/env/lib/python3.11/site-packages/urllib3/util/connection.py", line 73, in create_connection
    sock.connect(sa)
ConnectionRefusedError: [Errno 111] Connection refused

The above exception was the direct cause of the following exception:

Traceback (most recent call last):
  File "/home/pi/SWS3025/env/lib/python3.11/site-packages/urllib3/connectionpool.py", line 789, in urlopen
    response = self._make_request(
               ^^^^^^^^^^^^^^^^^^^
  File "/home/pi/SWS3025/env/lib/python3.11/site-packages/urllib3/connectionpool.py", line 495, in _make_request
    conn.request(
  File "/home/pi/SWS3025/env/lib/python3.11/site-packages/urllib3/connection.py", line 398, in request
    self.endheaders()
  File "/usr/lib/python3.11/http/client.py", line 1277, in endheaders
    self._send_output(message_body, encode_chunked=encode_chunked)
  File "/usr/lib/python3.11/http/client.py", line 1037, in _send_output
    self.send(msg)
  File "/usr/lib/python3.11/http/client.py", line 975, in send
    self.connect()
  File "/home/pi/SWS3025/env/lib/python3.11/site-packages/urllib3/connection.py", line 236, in connect
    self.sock = self._new_conn()
                ^^^^^^^^^^^^^^^^
  File "/home/pi/SWS3025/env/lib/python3.11/site-packages/urllib3/connection.py", line 211, in _new_conn
    raise NewConnectionError(
urllib3.exceptions.NewConnectionError: <urllib3.connection.HTTPConnection object at 0x7f7893c0d0>: Failed to establish a new connection: [Errno 111] Connection refused

The above exception was the direct cause of the following exception:

Traceback (most recent call last):
  File "/home/pi/SWS3025/env/lib/python3.11/site-packages/requests/adapters.py", line 667, in send
    resp = conn.urlopen(
           ^^^^^^^^^^^^^
  File "/home/pi/SWS3025/env/lib/python3.11/site-packages/urllib3/connectionpool.py", line 843, in urlopen
    retries = retries.increment(
              ^^^^^^^^^^^^^^^^^^
  File "/home/pi/SWS3025/env/lib/python3.11/site-packages/urllib3/util/retry.py", line 519, in increment
    raise MaxRetryError(_pool, url, reason) from reason  # type: ignore[arg-type]
    ^^^^^^^^^^^^^^^^^^^^^^^^^^^^^^^^^^^^^^^^^^^^^^^^^^^
urllib3.exceptions.MaxRetryError: HTTPConnectionPool(host='192.168.92.106', port=5000): Max retries exceeded with url: /receive_data (Caused by NewConnectionError('<urllib3.connection.HTTPConnection object at 0x7f7893c0d0>: Failed to establish a new connection: [Errno 111] Connection refused'))

During handling of the above exception, another exception occurred:

Traceback (most recent call last):
  File "/home/pi/SWS3025/Weather/./predict.py", line 203, in <module>
    send_data_to_server(current_weather, predicted_weather)
  File "/home/pi/SWS3025/Weather/./predict.py", line 159, in send_data_to_server
    response = requests.post(url, json=data)
               ^^^^^^^^^^^^^^^^^^^^^^^^^^^^^
  File "/home/pi/SWS3025/env/lib/python3.11/site-packages/requests/api.py", line 115, in post
    return request("post", url, data=data, json=json, **kwargs)
           ^^^^^^^^^^^^^^^^^^^^^^^^^^^^^^^^^^^^^^^^^^^^^^^^^^^^
  File "/home/pi/SWS3025/env/lib/python3.11/site-packages/requests/api.py", line 59, in request
    return session.request(method=method, url=url, **kwargs)
           ^^^^^^^^^^^^^^^^^^^^^^^^^^^^^^^^^^^^^^^^^^^^^^^^^
  File "/home/pi/SWS3025/env/lib/python3.11/site-packages/requests/sessions.py", line 589, in request
    resp = self.send(prep, **send_kwargs)
           ^^^^^^^^^^^^^^^^^^^^^^^^^^^^^^
  File "/home/pi/SWS3025/env/lib/python3.11/site-packages/requests/sessions.py", line 703, in send
    r = adapter.send(request, **kwargs)
        ^^^^^^^^^^^^^^^^^^^^^^^^^^^^^^^
  File "/home/pi/SWS3025/env/lib/python3.11/site-packages/requests/adapters.py", line 700, in send
    raise ConnectionError(e, request=request)
requests.exceptions.ConnectionError: HTTPConnectionPool(host='192.168.92.106', port=5000): Max retries exceeded with url: /receive_data (Caused by NewConnectionError('<urllib3.connection.HTTPConnection object at 0x7f7893c0d0>: Failed to establish a new connection: [Errno 111] Connection refused'))
